<?xml version="1.0"?>
<robot name="simple_humanoid">

  <!-- Base Link -->
  <link name="base_link">
    <visual>
      <geometry>
        <box size="0.2 0.3 0.1"/>
      </geometry>
      <material name="blue">
        <color rgba="0 0 1 1"/>
      </material>
    </visual>
  </link>

  <!-- Torso Link -->
  <link name="torso">
    <visual>
      <geometry>
        <box size="0.2 0.3 0.5"/>
      </geometry>
      <material name="blue"/>
    </visual>
  </link>

  <joint name="base_to_torso" type="fixed">
    <parent link="base_link"/>
    <child link="torso"/>
    <origin xyz="0 0 0.3"/>
  </joint>

  <!-- Head Link -->
  <link name="head">
    <visual>
      <geometry>
        <sphere radius="0.1"/>
      </geometry>
      <material name="white">
        <color rgba="1 1 1 1"/>
      </material>
    </visual>
  </link>

  <joint name="torso_to_head" type="continuous">
    <parent link="torso"/>
    <child link="head"/>
    <origin xyz="0 0 0.3"/>
    <axis xyz="0 0 1"/>
  </joint>

</robot>
